Workbook
Name Slicer_Region: #N/A

Sheet Dashboard
A1: SALES PERFORMANCE MIS DASHBOARD — FY 2024
A2: Prepared By: Amit Lentham | Date Period: Jan 2024 - Dec 2024 | Project Made : Feb-Mar 2025
B3: =MIS_Report!A6 -> Total Revenue | E3: =MIS_Report!A7 -> Total Orders | H3: =MIS_Report!A8 -> Total Units Sold | K3: =MIS_Report!A9 -> Avg Order Value
B4: =MIS_Report!B6 -> 81536199 | E4: =MIS_Report!B7 -> 300 | H4: =MIS_Report!B8 -> 3144 | K4: =MIS_Report!B9 -> 271787.33

Sheet MIS_Report
A1: Sales Performance MIS Report — FY 2024
A2: Prepared By: Amit Lentham | Date Period: Jan 2024 - Dec 2024
A3: Project Made : Feb-Mar 2025
A4: KEY PERFORMANCE INDICATORS
A6: Total Revenue | B6: =SUM(cleaned_data!K2:K301) -> 81536199
A7: Total Orders | B7: =COUNTA(cleaned_data!A2:A301) -> 300
A8: Total Units Sold | B8: =SUM(cleaned_data!I2:I301) -> 3144
A9: Avg Order Value | B9: =B6/B7 -> 271787.33
A11: MONTH-WISE SALES SUMMARY
A12: Month | B12: Total Revenue | C12: Total Units | D12: Total Orders | E12: Avg Order Value
A13: Jan-2024 | B13: =SUMIF(cleaned_data!$L$2:$L$301,MIS_Report!$A13,cleaned_data!$K$2:$K$301) -> 8147926 | C13: =SUMIF(cleaned_data!$L$2:$L$301,MIS_Report!$A13,cleaned_data!$I$2:$I$301) -> 306 | D13: =COUNTIF(cleaned_data!$L$2:$L$301,MIS_Report!A13) -> 26 | E13: =B13/D13 -> 313381.77
A14: Feb-2024 | B14: =SUMIF(cleaned_data!$L$2:$L$301,MIS_Report!$A14,cleaned_data!$K$2:$K$301) -> 6138144 | C14: =SUMIF(cleaned_data!$L$2:$L$301,MIS_Report!$A14,cleaned_data!$I$2:$I$301) -> 242 | D14: =COUNTIF(cleaned_data!$L$2:$L$301,MIS_Report!A14) -> 27 | E14: =B14/D14 -> 227338.67
A15: Mar-2024 | B15: =SUMIF(cleaned_data!$L$2:$L$301,MIS_Report!$A15,cleaned_data!$K$2:$K$301) -> 4444904 | C15: =SUMIF(cleaned_data!$L$2:$L$301,MIS_Report!$A15,cleaned_data!$I$2:$I$301) -> 213 | D15: =COUNTIF(cleaned_data!$L$2:$L$301,MIS_Report!A15) -> 18 | E15: =B15/D15 -> 246939.11
A16: Apr-2024 | B16: =SUMIF(cleaned_data!$L$2:$L$301,MIS_Report!$A16,cleaned_data!$K$2:$K$301) -> 4832210 | C16: =SUMIF(cleaned_data!$L$2:$L$301,MIS_Report!$A16,cleaned_data!$I$2:$I$301) -> 206 | D16: =COUNTIF(cleaned_data!$L$2:$L$301,MIS_Report!A16) -> 25 | E16: =B16/D16 -> 193288.4
A17: May-2024 | B17: =SUMIF(cleaned_data!$L$2:$L$301,MIS_Report!$A17,cleaned_data!$K$2:$K$301) -> 5871322 | C17: =SUMIF(cleaned_data!$L$2:$L$301,MIS_Report!$A17,cleaned_data!$I$2:$I$301) -> 245 | D17: =COUNTIF(cleaned_data!$L$2:$L$301,MIS_Report!A17) -> 26 | E17: =B17/D17 -> 225820.08
A18: Jun-2024 | B18: =SUMIF(cleaned_data!$L$2:$L$301,MIS_Report!$A18,cleaned_data!$K$2:$K$301) -> 7145156 | C18: =SUMIF(cleaned_data!$L$2:$L$301,MIS_Report!$A18,cleaned_data!$I$2:$I$301) -> 288 | D18: =COUNTIF(cleaned_data!$L$2:$L$301,MIS_Report!A18) -> 24 | E18: =B18/D18 -> 297714.83
A19: Jul-2024 | B19: =SUMIF(cleaned_data!$L$2:$L$301,MIS_Report!$A19,cleaned_data!$K$2:$K$301) -> 6592159 | C19: =SUMIF(cleaned_data!$L$2:$L$301,MIS_Report!$A19,cleaned_data!$I$2:$I$301) -> 284 | D19: =COUNTIF(cleaned_data!$L$2:$L$301,MIS_Report!A19) -> 27 | E19: =B19/D19 -> 244154.04
A20: Aug-2024 | B20: =SUMIF(cleaned_data!$L$2:$L$301,MIS_Report!$A20,cleaned_data!$K$2:$K$301) -> 6105214 | C20: =SUMIF(cleaned_data!$L$2:$L$301,MIS_Report!$A20,cleaned_data!$I$2:$I$301) -> 213 | D20: =COUNTIF(cleaned_data!$L$2:$L$301,MIS_Report!A20) -> 19 | E20: =B20/D20 -> 321327.05
A21: Sep-2024 | B21: =SUMIF(cleaned_data!$L$2:$L$301,MIS_Report!$A21,cleaned_data!$K$2:$K$301) -> 11654128 | C21: =SUMIF(cleaned_data!$L$2:$L$301,MIS_Report!$A21,cleaned_data!$I$2:$I$301) -> 426 | D21: =COUNTIF(cleaned_data!$L$2:$L$301,MIS_Report!A21) -> 36 | E21: =B21/D21 -> 323725.78
A22: Oct-2024 | B22: =SUMIF(cleaned_data!$L$2:$L$301,MIS_Report!$A22,cleaned_data!$K$2:$K$301) -> 9628802 | C22: =SUMIF(cleaned_data!$L$2:$L$301,MIS_Report!$A22,cleaned_data!$I$2:$I$301) -> 344 | D22: =COUNTIF(cleaned_data!$L$2:$L$301,MIS_Report!A22) -> 34 | E22: =B22/D22 -> 283200.06
A23: Nov-2024 | B23: =SUMIF(cleaned_data!$L$2:$L$301,MIS_Report!$A23,cleaned_data!$K$2:$K$301) -> 3123725 | C23: =SUMIF(cleaned_data!$L$2:$L$301,MIS_Report!$A23,cleaned_data!$I$2:$I$301) -> 120 | D23: =COUNTIF(cleaned_data!$L$2:$L$301,MIS_Report!A23) -> 15 | E23: =B23/D23 -> 208248.33
A24: Dec-2024 | B24: =SUMIF(cleaned_data!$L$2:$L$301,MIS_Report!$A24,cleaned_data!$K$2:$K$301) -> 7852509 | C24: =SUMIF(cleaned_data!$L$2:$L$301,MIS_Report!$A24,cleaned_data!$I$2:$I$301) -> 257 | D24: =COUNTIF(cleaned_data!$L$2:$L$301,MIS_Report!A24) -> 23 | E24: =B24/D24 -> 341413.43
A25: Grand Total | B25: =SUM(B13:B24) -> 81536199 | C25: =SUM(C13:C24) -> 3144 | D25: =SUM(D13:D24) -> 300
A27: REGION-WISE SALES SUMMARY
A28: Region | B28: Total Revenue | C28: Total Units | D28: Total Orders | E28: Avg Order Value
A29: North | B29: =SUMIF(cleaned_data!$C$2:$C$301,MIS_Report!A29,cleaned_data!$K$2:$K$301) -> 18429976 | C29: =SUMIF(cleaned_data!$C$2:$C$301,MIS_Report!$A29,cleaned_data!$I$2:$I$301) -> 732 | D29: =COUNTIF(cleaned_data!$C$2:$C$301,MIS_Report!A29) -> 73 | E29: =B29/D29 -> 252465.42
A30: South | B30: =SUMIF(cleaned_data!$C$2:$C$301,MIS_Report!A30,cleaned_data!$K$2:$K$301) -> 24751542 | C30: =SUMIF(cleaned_data!$C$2:$C$301,MIS_Report!$A30,cleaned_data!$I$2:$I$301) -> 892 | D30: =COUNTIF(cleaned_data!$C$2:$C$301,MIS_Report!A30) -> 82 | E30: =B30/D30 -> 301848.07
A31: East | B31: =SUMIF(cleaned_data!$C$2:$C$301,MIS_Report!A31,cleaned_data!$K$2:$K$301) -> 18136368 | C31: =SUMIF(cleaned_data!$C$2:$C$301,MIS_Report!$A31,cleaned_data!$I$2:$I$301) -> 688 | D31: =COUNTIF(cleaned_data!$C$2:$C$301,MIS_Report!A31) -> 65 | E31: =B31/D31 -> 279021.05
A32: West | B32: =SUMIF(cleaned_data!$C$2:$C$301,MIS_Report!A32,cleaned_data!$K$2:$K$301) -> 18480996 | C32: =SUMIF(cleaned_data!$C$2:$C$301,MIS_Report!$A32,cleaned_data!$I$2:$I$301) -> 740 | D32: =COUNTIF(cleaned_data!$C$2:$C$301,MIS_Report!A32) -> 72 | E32: =B32/D32 -> 256680.5
A33: Unknown | B33: =SUMIF(cleaned_data!$C$2:$C$301,MIS_Report!A33,cleaned_data!$K$2:$K$301) -> 1737317 | C33: =SUMIF(cleaned_data!$C$2:$C$301,MIS_Report!$A33,cleaned_data!$I$2:$I$301) -> 92 | D33: =COUNTIF(cleaned_data!$C$2:$C$301,MIS_Report!A33) -> 8 | E33: =B33/D33 -> 217164.62
A34: Grand Total | B34: =SUM(B29:B33) -> 81536199 | C34: =SUM(C29:C33) -> 3144 | D34: =SUM(D29:D33) -> 300 | E34: =B34/D34 -> 271787.33

Sheet cleaned_data
A1: Order_ID | B1: Order_Date | C1: Region | D1: City | E1: Salesman | F1: Category | G1: Sub_Category | H1: Product | I1: Units_Sold | J1: Unit_Price | K1: Total_Revenue | L1: Month_Year | M1: Quarter
A2: ORD1000 | B2: 45545 | C2: South | D2: Hyderabad | E2: Priya Mehta | F2: Electronics | G2: Mobile | H2: iPhone | I2: 16 | J2: 42902 | K2: =I2*J2 -> 686432 | L2: =TEXT(B2,"MMM-YYYY") -> Sep-2024 | M2: =IF(MONTH(L2)<=3,"Q1",IF(MONTH(L2)<=6,"Q2",IF(MONTH(L2)<=9,"Q3","Q4"))) -> Q3
A3: ORD1001 | B3: 45491 | C3: East | D3: Kolkata | E3: Priya Mehta | F3: Electronics | G3: Mobile | H3: iPhone | I3: 20 | J3: 338 | K3: =I3*J3 -> 6760 | L3: =TEXT(B3,"MMM-YYYY") -> Jul-2024 | M3: =IF(MONTH(L3)<=3,"Q1",IF(MONTH(L3)<=6,"Q2",IF(MONTH(L3)<=9,"Q3","Q4"))) -> Q3
A4: ORD1002 | B4: 45454 | C4: East | D4: Bhubaneswar | E4: Rahul Sharma | F4: Office Supplies | G4: Pen | H4: Gel Pen | I4: 1 | J4: 1867 | K4: =I4*J4 -> 1867 | L4: =TEXT(B4,"MMM-YYYY") -> Jun-2024 | M4: =IF(MONTH(L4)<=3,"Q1",IF(MONTH(L4)<=6,"Q2",IF(MONTH(L4)<=9,"Q3","Q4"))) -> Q2
A5: ORD1003 | B5: 45306 | C5: North | D5: Jaipur | E5: Karan Singh | F5: Office Supplies | G5: Pen | H5: Ball Pen | I5: 8 | J5: 28897 | K5: =I5*J5 -> 231176 | L5: =TEXT(B5,"MMM-YYYY") -> Jan-2024 | M5: =IF(MONTH(L5)<=3,"Q1",IF(MONTH(L5)<=6,"Q2",IF(MONTH(L5)<=9,"Q3","Q4"))) -> Q1
A6: ORD1004 | B6: 45638 | C6: East | D6: Patna | E6: Unknown | F6: Electronics | G6: Mobile | H6: iPhone | I6: 15 | J6: 19191 | K6: =I6*J6 -> 287865 | L6: =TEXT(B6,"MMM-YYYY") -> Dec-2024 | M6: =IF(MONTH(L6)<=3,"Q1",IF(MONTH(L6)<=6,"Q2",IF(MONTH(L6)<=9,"Q3","Q4"))) -> Q4
A7: ORD1005 | B7: 45387 | C7: North | D7: Jaipur | E7: Neha Gupta | F7: Office Supplies | G7: Stapler | H7: Small Stapler | I7: 4 | J7: 48902 | K7: =I7*J7 -> 195608 | L7: =TEXT(B7,"MMM-YYYY") -> Apr-2024 | M7: =IF(MONTH(L7)<=3,"Q1",IF(MONTH(L7)<=6,"Q2",IF(MONTH(L7)<=9,"Q3","Q4"))) -> Q2
A8: ORD1006 | B8: 45551 | C8: West | D8: Ahmedabad | E8: Amit Verma | F8: Office Supplies | G8: Stapler | H8: Small Stapler | I8: 10 | J8: 18822 | K8: =I8*J8 -> 188220 | L8: =TEXT(B8,"MMM-YYYY") -> Sep-2024 | M8: =IF(MONTH(L8)<=3,"Q1",IF(MONTH(L8)<=6,"Q2",IF(MONTH(L8)<=9,"Q3","Q4"))) -> Q3
A9: ORD1007 | B9: 45537 | C9: East | D9: Patna | E9: Amit Verma | F9: Furniture | G9: Cabinet | H9: Wood Cabinet | I9: 13 | J9: 27352 | K9: =I9*J9 -> 355576 | L9: =TEXT(B9,"MMM-YYYY") -> Sep-2024 | M9: =IF(MONTH(L9)<=3,"Q1",IF(MONTH(L9)<=6,"Q2",IF(MONTH(L9)<=9,"Q3","Q4"))) -> Q3
A10: ORD1008 | B10: 45336 | C10: South | D10: Chennai | E10: Priya Mehta | F10: Office Supplies | G10: Stapler | H10: Small Stapler | I10: 17 | J10: 7273 | K10: =I10*J10 -> 123641 | L10: =TEXT(B10,"MMM-YYYY") -> Feb-2024 | M10: =IF(MONTH(L10)<=3,"Q1",IF(MONTH(L10)<=6,"Q2",IF(MONTH(L10)<=9,"Q3","Q4"))) -> Q1
A11: ORD1009 | B11: 45307 | C11: South | D11: Hyderabad | E11: Priya Mehta | F11: Furniture | G11: Table | H11: Office Desk | I11: 2 | J11: 20419 | K11: =I11*J11 -> 40838 | L11: =TEXT(B11,"MMM-YYYY") -> Jan-2024 | M11: =IF(MONTH(L11)<=3,"Q1",IF(MONTH(L11)<=6,"Q2",IF(MONTH(L11)<=9,"Q3","Q4"))) -> Q1
A12: ORD1010 | B12: 45408 | C12: East | D12: Patna | E12: Rahul Sharma | F12: Electronics | G12: Laptop | H12: Lenovo Laptop | I12: 7 | J12: 35564 | K12: =I12*J12 -> 248948 | L12: =TEXT(B12,"MMM-YYYY") -> Apr-2024 | M12: =IF(MONTH(L12)<=3,"Q1",IF(MONTH(L12)<=6,"Q2",IF(MONTH(L12)<=9,"Q3","Q4"))) -> Q2
A13: ORD1011 | B13: 45527 | C13: South | D13: Chennai | E13: Neha Gupta | F13: Office Supplies | G13: Notebook | H13: Classmate Notebook | I13: 18 | J13: 40107 | K13: =I13*J13 -> 721926 | L13: =TEXT(B13,"MMM-YYYY") -> Aug-2024 | M13: =IF(MONTH(L13)<=3,"Q1",IF(MONTH(L13)<=6,"Q2",IF(MONTH(L13)<=9,"Q3","Q4"))) -> Q3
... A301: ORD1299 | B301: 45457 | C301: West | D301: Ahmedabad | E301: Priya Mehta | F301: Office Supplies | G301: Notebook | H301: Classmate Notebook | I301: 13 | J301: 35344 | K301: =I301*J301 -> 459472 | L301: =TEXT(B301,"MMM-YYYY") -> Jun-2024 | M301: =IF(MONTH(L301)<=3,"Q1",IF(MONTH(L301)<=6,"Q2",IF(MONTH(L301)<=9,"Q3","Q4"))) -> Q2

Sheet Region_Revenue
A3: Row Labels | B3: Sum of Total_Revenue
A4: East | B4: 18136368
A5: North | B5: 18429976
A6: South | B6: 24751542
A7: Unknown | B7: 1737317
A8: West | B8: 18480996
A9: Grand Total | B9: 81536199

Sheet Month_Trend
A2: Row Labels | B2: Sum of Total_Revenue | C2: Sum of Units_Sold
A3: Jan | B3: 8147926 | C3: 306
A4: Feb | B4: 6138144 | C4: 242
A5: Mar | B5: 4444904 | C5: 213
A6: Apr | B6: 4832210 | C6: 206
A7: May | B7: 5871322 | C7: 245
A8: Jun | B8: 7145156 | C8: 288
A9: Jul | B9: 6592159 | C9: 284
A10: Aug | B10: 6105214 | C10: 213
A11: Sep | B11: 11654128 | C11: 426
A12: Oct | B12: 9628802 | C12: 344
A13: Nov | B13: 3123725 | C13: 120
A14: Dec | B14: 7852509 | C14: 257
A15: Grand Total | B15: 81536199 | C15: 3144

Sheet Category_Revenue
A3: Row Labels | B3: Sum of Total_Revenue | C3: Sum of Units_Sold
A4: Electronics | B4: 20484512 | C4: 820
A5: Laptop | B5: 6341750 | C5: 248
A6: Mobile | B6: 8450343 | C6: 347
A7: Printer | B7: 5692419 | C7: 225
A8: Furniture | B8: 29047738 | C8: 1143
A9: Cabinet | B9: 11585638 | C9: 406
A10: Chair | B10: 8749253 | C10: 350
A11: Table | B11: 8712847 | C11: 387
A12: Office Supplies | B12: 32003949 | C12: 1181
A13: Notebook | B13: 11661961 | C13: 410
A14: Pen | B14: 12572513 | C14: 427
A15: Stapler | B15: 7769475 | C15: 344
A16: Grand Total | B16: 81536199 | C16: 3144
A18: Row Labels | B18: Sum of Total_Revenue | C18: Sum of Units_Sold
A19: Electronics | B19: 20484512 | C19: 820
A20: Furniture | B20: 29047738 | C20: 1143
A21: Office Supplies | B21: 32003949 | C21: 1181
A22: Grand Total | B22: 81536199 | C22: 3144

Sheet Salesperson_Performance
A3: Row Labels | B3: Sum of Total_Revenue | C3: Sum of Units_Sold | D3: Count of Order_ID
A4: Amit Verma | B4: 18291400 | C4: 658 | D4: 62
A5: Karan Singh | B5: 13694982 | C5: 537 | D5: 55
A6: Neha Gupta | B6: 18931680 | C6: 747 | D6: 69
A7: Priya Mehta | B7: 15862368 | C7: 652 | D7: 60
A8: Rahul Sharma | B8: 12957575 | C8: 468 | D8: 46
A9: Unknown | B9: 1798194 | C9: 82 | D9: 8
A10: Grand Total | B10: 81536199 | C10: 3144 | D10: 300

Sheet Quarter_Summary
A3: Sum of Total_Revenue | B3: Column Labels
A4: Row Labels | B4: Electronics | C4: Furniture | D4: Office Supplies | E4: Grand Total
A5: Q1 | B5: 5407752 | C5: 7017554 | D5: 6305668 | E5: 18730974
A6: Q2 | B6: 6501040 | C6: 7009480 | D6: 4338168 | E6: 17848688
A7: Q3 | B7: 5601236 | C7: 8118016 | D7: 10632249 | E7: 24351501
A8: Q4 | B8: 2974484 | C8: 6902688 | D8: 10727864 | E8: 20605036
A9: Grand Total | B9: 20484512 | C9: 29047738 | D9: 32003949 | E9: 81536199

Sheet Order_LOOKUP_Tool
A1: ORDER LOOKUP TOOL
A3: Order ID | B3: Region | C3: Salesman | D3: Product | E3: Total_Revenue
A4: ORD1000 | B4: =VLOOKUP($A$4,cleaned_data!$A$1:$M$301,MATCH(B$3,cleaned_data!$A$1:$M$1,0),FALSE) -> South | C4: =VLOOKUP($A$4,cleaned_data!$A$1:$M$301,MATCH(C$3,cleaned_data!$A$1:$M$1,0),FALSE) -> Priya Mehta | D4: =VLOOKUP($A$4,cleaned_data!$A$1:$M$301,MATCH(D$3,cleaned_data!$A$1:$M$1,0),FALSE) -> iPhone | E4: =VLOOKUP($A$4,cleaned_data!$A$1:$M$301,MATCH(E$3,cleaned_data!$A$1:$M$1,0),FALSE) -> 686432

Sheet Raw_Data
A1: Order_ID | B1: Order_Date | C1: Region | D1: City | E1: Salesman | F1: Category | G1: Sub_Category | H1: Product | I1: Units_Sold | J1: Unit_Price
A2: ORD1000 | B2: 10-09-2024 | C2: South | D2: Hyderabad | E2: Priya Mehta | F2: Electronics | G2: Mobile | H2: iPhone | I2: 16 | J2: 42902
A3: ORD1001 | B3: 18/07/24 | D3: Kolkata | E3: Priya Mehta | F3: Electronics | G3: Mobile | H3: iPhone | I3: 20 | J3: 338
A4: ORD1002 | B4: 2024-06-11 | C4: East | D4: Bhubaneswar | E4: Rahul Sharma | F4: Office Supplies | G4: Pen | H4: Gel Pen | I4: 1 | J4: 1867
A5: ORD1003 | B5: 15/01/24 | C5: North | D5: Jaipur | E5: Karan Singh | F5: Office Supplies | G5: Pen | H5: Ball Pen | I5: 8 | J5: 28897
A6: ORD1004 | B6: 2024-12-12 | C6: East | D6: Patna | E6: Unknown | F6: Electronics | G6: Mobile | H6: iPhone | I6: 15 | J6: 19191
A7: ORD1005 | B7: 05/04/24 | C7: North | D7: Jaipur | E7: Neha Gupta | F7: Office Supplies | G7: Stapler | H7: Small Stapler | I7: 4 | J7: 48902
A8: ORD1006 | B8: 45551 | C8: West | D8: Ahmedabad | E8: Amit Verma | F8: Office Supplies | G8: Stapler | H8: Small Stapler | I8: 10 | J8: 18822
A9: ORD1007 | B9: 2024-09-02 | C9: East | D9: Patna | E9: Amit Verma | F9: Furniture | G9: Cabinet | H9: Wood Cabinet | I9: 13 | J9: 27352
A10: ORD1008 | B10: 14 Feb 2024 | C10: South | D10: Chennai | E10: Priya Mehta | F10: Office Supplies | G10: Stapler | H10: Small Stapler | I10: 17 units | J10: 7273
A11: ORD1009 | B11: 16 Jan 2024 | C11: Soth | D11: Hyderabad | E11: Priya Mehta | F11: Furniture | G11: Table | H11: Office Desk | I11: 2 | J11: 20419
A12: ORD1010 | B12: 04/26/2024 | C12: East | D12: Patna | E12: Rahul Sharma | F12: Electronics | G12: Laptop | H12: Lenovo Laptop | I12: 7 units | J12: 35564
A13: ORD1011 | B13: 23/08/24 | C13: South | D13: Chennai | E13: Neha Gupta | F13: Office Supplies | G13: Notebook | H13: Classmate Notebook | I13: 18 | J13: 40107
A14: ORD1012 | B14: 45557 | C14: North | D14: Jaipur | E14: Karan Singh | F14: Office Supplies | G14: Stapler | H14: Small Stapler | I14: 7 | J14: 28124
A15: ORD1013 | B15: 09/15/2024 | C15: north | D15: Jaipur | E15: Priya Mehta | F15: Furniture | G15: Cabinet | H15: Wood Cabinet | I15: 16 | J15: 23582
A16: ORD1014 | B16: 22 Aug 2024 | C16: East | D16: Bhubaneswar | E16: Karan Singh | F16: Electronics | G16: Printer | H16: Canon Printer | I16: 1 | J16: 15247
A17: ORD1015 | B17: 09 Oct 2024 | C17: South | D17: Unknown | E17: neha gupta | F17: Office Supplies | G17: Pen | H17: Gel Pen | I17: 2 | J17: 44313
A18: ORD1016 | B18: 23-05-2024 | C18: North | D18: Delhi | E18: Amit Verma | F18: Electronics | G18: Mobile | H18: iPhone | I18: 9 | J18: 7375
A19: ORD1017 | B19: 03/22/2024 | C19: South | D19: Chennai | E19: Neha Gupta | F19: Furniture | G19: Chair | H19: Office Chair | I19: 17 units | J19: 11219
A20: ORD1018 | B20: 45651 | C20: West | D20: Ahmedabad | E20: Neha Gupta | F20: Office Supplies | G20: Notebook | H20: Classmate Notebook | I20: 16 | J20: 31249
A21: ORD1019 | B21: 45507 | C21: North | D21: Delhi | E21: amit verma | F21: Furniture | G21: Table | H21: Office Desk | I21: 9 | J21: 7327
A22: ORD1020 | B22: 11-01-2024 | C22: West | D22: Ahmedabad | E22: Amit Verma | F22: Office Supplies | G22: Pen | H22: Ball Pen | I22: 1 | J22: 26238
A23: ORD1021 | B23: 26-12-2024 | C23: Soth | D23: Bangalore | E23: Karan Singh | F23: Office Supplies | G23: Pen | H23: Ball Pen | I23: 14 | J23: 35897
A24: ORD1022 | B24: 24/04/24 | C24: South | D24: Hyderabad | E24: Karan Singh | F24: Office Supplies | G24: Stapler | H24: Small Stapler | I24: 1 | J24: 26080
A25: ORD1023 | B25: 45444 | C25: West | D25: Ahmedabad | E25: Amit Verma | F25: Office Supplies | G25: Notebook | H25: Classmate Notebook | I25: 7 | J25: 3309
A26: ORD1024 | B26: 2024-03-22 | C26: WEST | D26: Mumbai | F26: Electronics | G26: Mobile | H26: Samsung Phone | I26: 19 | J26: 16738
A27: ORD1025 | B27: 45583 | C27: South | D27: Bangalore | E27: Priya Mehta | F27: Office Supplies | G27: Pen | H27: Gel Pen | I27: 6 | J27: 46338
A28: ORD1026 | B28: 04/15/2024 | C28: Unknown | D28: Jaipur | E28: Karan Singh | F28: Electronics | G28: Mobile | H28: iPhone | I28: 14 | J28: 38958
A29: ORD1027 | B29: 31 May 2024 | C29: Soth | D29: Chennai | E29: Karan Singh | F29: Electronics | G29: Printer | H29: Canon Printer | I29: 16 | J29: 1327
A30: ORD1028 | B30: 21 Mar 2024 | D30: Ahmedabad | E30: Amit Verma | F30: Furniture | G30: Table | H30: Study Table | I30: 11 | J30: 37119
A31: ORD1029 | B31: 45637 | C31: South | D31: Chennai | E31: Rahul Sharma | F31: Furniture | G31: Chair | H31: Plastic Chair | I31: 13 | J31: 36089
A32: ORD1030 | B32: 03-02-2024 | C32: West | D32: Ahmedabad | E32: Rahul Sharma | F32: Office Supplies | G32: Notebook | H32: Classmate Notebook | I32: 3 | J32: 8917
A33: ORD1031 | B33: 19/06/24 | C33: South | D33: Unknown | E33: Karan Singh | F33: Office Supplies | G33: Pen | H33: Ball Pen | I33: 17 | J33: 16930
A34: ORD1032 | B34: 45412 | C34: West | D34: Pune | E34: Karan Singh | F34: Furniture | G34: Chair | H34: Plastic Chair | I34: 16 | J34: 9070
A35: ORD1033 | B35: 13 Jul 2024 | C35: North | D35: Jaipur | E35: Amit Verma | F35: Electronics | G35: Mobile | H35: iPhone | I35: 5 | J35: 22541
A36: ORD1034 | B36: 45584 | C36: North | D36: Chandigarh | E36: Karan Singh | F36: Office Supplies | G36: Notebook | H36: Classmate Notebook | I36: 8 | J36: 37291
A37: ORD1035 | B37: 22-08-2024 | C37: North | D37: Jaipur | E37: Neha Gupta | F37: Furniture | G37: Table | H37: Study Table | I37: 4 | J37: 3198
A38: ORD1036 | B38: 16-02-2024 | C38: West | D38: Mumbai | E38: Priya Mehta | F38: Office Supplies | G38: Stapler | H38: Small Stapler | I38: 4 | J38: 2822
A39: ORD1037 | B39: 02/29/2024 | C39: South | D39: Bangalore | E39: Priya Mehta | F39: Office Supplies | G39: Notebook | H39: Classmate Notebook | I39: 6 | J39: 44822
A40: ORD1038 | B40: 07/12/2024 | C40: South | D40: Bangalore | E40: Karan Singh | F40: Office Supplies | G40: Pen | H40: Ball Pen | I40: 10 | J40: 36258
...
